{
 "cells": [
  {
   "cell_type": "code",
   "execution_count": 6,
   "metadata": {},
   "outputs": [
    {
     "name": "stdout",
     "output_type": "stream",
     "text": [
      "Using input format: fiftyone.types.dataset_types.YOLOv5Dataset\n",
      "Using export format: fiftyone.types.dataset_types.COCODetectionDataset\n",
      "Loading dataset from '/home/s52melba/dataset_bee_annotated/val'\n",
      " 100% |█████████████████| 384/384 [1.1s elapsed, 0s remaining, 353.3 samples/s]         \n",
      "Exporting dataset to '/home/s52melba/dataset_bee_annotated/val_coco'\n",
      "Directory '/home/s52melba/dataset_bee_annotated/val_coco' already exists; export will be merged with existing files\n",
      "  51% |████████|--------| 195/384 [1.6m elapsed, 1.3m remaining, 3.0 samples/s]    \n",
      "Traceback (most recent call last):\n",
      "  File \"/home/s52melba/anaconda3/envs/bee/lib/python3.11/site-packages/fiftyone/utils/data/exporters.py\", line 930, in _write_image_dataset\n",
      "    dataset_exporter.export_sample(\n",
      "  File \"/home/s52melba/anaconda3/envs/bee/lib/python3.11/site-packages/fiftyone/utils/coco.py\", line 825, in export_sample\n",
      "    out_image_path, uuid = self._media_exporter.export(image_or_path)\n",
      "                           ^^^^^^^^^^^^^^^^^^^^^^^^^^^^^^^^^^^^^^^^^^\n",
      "  File \"/home/s52melba/anaconda3/envs/bee/lib/python3.11/site-packages/fiftyone/utils/data/exporters.py\", line 1314, in export\n",
      "    etau.copy_file(media_path, outpath)\n",
      "  File \"/home/s52melba/anaconda3/envs/bee/lib/python3.11/site-packages/eta/core/utils.py\", line 2441, in copy_file\n",
      "    shutil.copy(inpath, outpath)\n",
      "  File \"/home/s52melba/anaconda3/envs/bee/lib/python3.11/shutil.py\", line 431, in copy\n",
      "    copyfile(src, dst, follow_symlinks=follow_symlinks)\n",
      "  File \"/home/s52melba/anaconda3/envs/bee/lib/python3.11/shutil.py\", line 258, in copyfile\n",
      "    with open(dst, 'wb') as fdst:\n",
      "OSError: [Errno 28] No space left on device\n",
      "\n",
      "During handling of the above exception, another exception occurred:\n",
      "\n",
      "Traceback (most recent call last):\n",
      "  File \"/home/s52melba/anaconda3/envs/bee/bin/fiftyone\", line 8, in <module>\n",
      "    sys.exit(main())\n",
      "             ^^^^^^\n",
      "  File \"/home/s52melba/anaconda3/envs/bee/lib/python3.11/site-packages/fiftyone/core/cli.py\", line 4715, in main\n",
      "    args.execute(args)\n",
      "  File \"/home/s52melba/anaconda3/envs/bee/lib/python3.11/site-packages/fiftyone/core/cli.py\", line 4698, in <lambda>\n",
      "    parser.set_defaults(execute=lambda args: command.execute(parser, args))\n",
      "                                             ^^^^^^^^^^^^^^^^^^^^^^^^^^^^^\n",
      "  File \"/home/s52melba/anaconda3/envs/bee/lib/python3.11/site-packages/fiftyone/core/cli.py\", line 369, in execute\n",
      "    foud.convert_dataset(\n",
      "  File \"/home/s52melba/anaconda3/envs/bee/lib/python3.11/site-packages/fiftyone/utils/data/converters.py\", line 135, in convert_dataset\n",
      "    dataset.export(dataset_exporter=dataset_exporter, overwrite=overwrite)\n",
      "  File \"/home/s52melba/anaconda3/envs/bee/lib/python3.11/site-packages/fiftyone/core/collections.py\", line 9161, in export\n",
      "    _export(\n",
      "  File \"/home/s52melba/anaconda3/envs/bee/lib/python3.11/site-packages/fiftyone/core/collections.py\", line 11900, in _export\n",
      "    foud.export_samples(\n",
      "  File \"/home/s52melba/anaconda3/envs/bee/lib/python3.11/site-packages/fiftyone/utils/data/exporters.py\", line 366, in export_samples\n",
      "    write_dataset(\n",
      "  File \"/home/s52melba/anaconda3/envs/bee/lib/python3.11/site-packages/fiftyone/utils/data/exporters.py\", line 433, in write_dataset\n",
      "    _write_image_dataset(\n",
      "  File \"/home/s52melba/anaconda3/envs/bee/lib/python3.11/site-packages/fiftyone/utils/data/e